Workbook

Sheet Start Here
A1: Routing Table, version 3
A2: Built 20 September 2026 for Distill. The spreadsheet is the source of truth; a browsable copy is published as an artifact.
A4: What this file is, in one paragraph
A5: When someone finishes telling the app what they take, buy and do, every item gets looked up here. The row says what kind of thing it is, whether a ring or watch can see its effect, how big that effect is likely to be, what the studies found, and the exact sentence the person should read about it on day one. This table is the product's brain and its voice at the same time.
A6: You never ask the person which tier something is in. The tier comes out of this table plus their own answers (how much they take, what for, where the idea came from). The order the app checks things in is written out below.
A7: Nothing in here diagnoses, treats or prevents anything. Every sentence is about a habit, a dose, or a study. Never about a condition.
A9: What changed in version 4
A10: The table routes on answers, not just names | B10: Five new columns per row. 'Follow-up question' says which question fires for the item (dose and form, frequency, clock time, nights a week, last used, still paying, or an automatic overlap check). 'Rule that flips the tier' is the exact threshold, written as a rule the engine can run: for magnesium, 'form = oxide or spray → form not absorbed; dose under 200 mg elemental → dose too low'. Magnesium glycinate at 400 mg and magnesium oxide at 100 mg are now the same row with two different outcomes, which is the whole point. Rows that need no question say 'none' and route as before.
A11: Why this is load-bearing | B11: The day-one drops screen is generated from Tier 2, and Tier 2 is generated almost entirely from these answers. Without the follow-up questions, almost nothing lands in Tier 2 and that screen is empty. With them, a typical stack produces several drops on day one. See the Worked Example sheet.
A12: Two new reasons for a day-one drop | B12: 'Not being used' (a device in a drawer, a membership with banked credits, an app still billing) and 'overlaps with something else' (two gym memberships, a studio that duplicates a plunge at home, a toner doing the serum's job, collagen gummies next to collagen powder). Both use the same logic as the supplement drops: no test needed, drop it now. The dollar amounts are much larger, because services cost more than powders.
A13: The target person changed, and the table followed | B13: The person with thirty bottles was the old target. The new one is the premium-gym member who spends on services, classes, treatments and skincare, and wants to look and feel good. That person might own two supplements, so the 'cut at least five things in 60 days' promise can't be kept from dose failures alone. Thirty-four new rows cover memberships, class packs, recovery studios, massage memberships, meal services, apps, and a skincare section, plus 19 overlap groups (Overlap Groups sheet).
A14: Skincare is a category now | B14: Sunscreen and retinoids get a 'keep' with the strongest evidence in the file. Toners, second hyaluronic serums, most eye creams, doubled exfoliants and oxidised vitamin C serums are day-one drops. Every skincare verdict is about a product, never about a person's skin.
A15: Magnesium merged | B15: The separate oxide row is gone; the form is now an answer to the magnesium question. Threonate and the spray stay separate because they're different products with different claims.
A17: What changed in version 3
A18: Expected effect size | B18: Every row a wearable can see now has a number: how big the effect is likely to be, in units of one person's normal night-to-night swing. Below 0.8, a two-week test would usually come back inconclusive, so those rows get the honest Tier 3 treatment instead of a test that's set up to fail. The table used to send 81 rows to Tier 1; after the gate it's a much shorter list, and almost all of it is timing and behaviour, not supplements. That is a real finding about the product: the testable core is what people do, not what they swallow.
A19: Run it anyway | B19: Gated rows still let the person choose to run the test, told up front what to expect. Their choice is the point of the product; we just stop pretending a small effect is likely to show.
A20: Read from history | B20: A new column says whether the app can learn about an item from the person's existing wearable data before any test: workouts and wake times are recorded automatically; alcohol, caffeine and supplements only if they've been tagging them in Oura or WHOOP; and alcohol nights have a recognisable pattern (HRV down, resting heart rate up, temperature up, all together) that the app can flag for them to confirm. This is how the day-one 'hypotheses' get made, and it's why the morning-after-drinks screen logs the night rather than assigning it.
A21: Observe only | B21: Some items must never be assigned as an 'on' day: alcohol, nicotine, cannabis, energy drinks, fat burners. The app only records those when they happen, and may assign 'off' days. We never tell anyone to drink.
A22: Fact-check flags | B22: Every Tier 2 row, and every row with a specific number in it, now carries a note saying exactly what to check and where to look. That's 90-odd rows, up from 2. Tier 2 rows tell someone to stop paying for something, so they are the exposure.
A23: Fixes | B23: Two double-parenthesis typos. The sauna habit row no longer carries the membership's cost. A stable key column for the engine. Cost per year as a live formula. A goal-to-number map so the routing has a defined metric for every goal.
A25: The four tiers, in plain words
A26: Tier 1: Tested on you | B26: A wearable can see it, it acts within hours, and the likely effect is big enough to show in two weeks. Three days on, three off, repeat. One number chosen before the start. One word at the end: kept, dropped, or inconclusive, always with the actual number.
A27: Tier 2: No test needed | B27: The answer is already known on day one. Five reasons: the dose is too low, the form isn't absorbed, it's been tested properly and found to do nothing, there's no known way it could work, or it duplicates something they already have. The person sees the money back immediately.
A28: Tier 3: Can't measure it | B28: Either a wearable is blind to it, or the likely effect is too small to see in two weeks. We say which. We show the cost per year and what the studies found, and offer a one-tap daily rating for things you'd feel rather than measure. Tier 3 is NOT 'drop': creatine, fibre, strength training and a personal trainer are Tier 3 and get a 'keep'.
A29: Protected | B29: Anything from a doctor, a blood test, a prescription, a hormone, or tied to a diagnosed condition. Never rated, tested, or suggested for dropping. In the count only if they want it there.
A31: The order the app checks things (top to bottom, first match wins)
A32: 1. Protected? | B32: Doctor or blood test source, prescription, hormone, clinical service, or a diagnosed condition named for it. Stop.
A33: 2. Safety note? | B33: Attach it. A few redirect to Protected (mouth tape with possible sleep apnoea; 5-HTP with an antidepressant).
A34: 3. Goal known? | B34: 'General health' or 'nothing specific' goes to Tier 3 as untestable, cost shown.
A35: 4. Settled without a test? | B35: Run the row's follow-up question. Dose below the floor, form not absorbed, evidence grade N for the goal, no way it could work: Tier 2 with the reason. Then the usage checks: last used over 30 days ago, or still paying and not using: Tier 2 (not being used). Then the overlap check: two or more items from the same overlap group: Tier 2 (overlaps with something else) for the one used less. The person is always shown both and asked which they'd keep.
A36: 5. Wearable can see it, acts fast, effect at least 0.8? | B36: Tier 1. Order the person's Tier 1 list by expected effect, largest first. Check the 'read from history' column: if the app already has weeks of on and off nights from tags or workouts, show that comparison as a day-one hypothesis before the test.
A37: 6. Wearable can see it, acts fast, effect under 0.8? | B37: Tier 3, 'effect too small to see in two weeks', with the option to run it anyway.
A38: 7. Wearable can see it but it's slow? | B38: Tier 1 in principle, queued. Never run 3-day blocks on it.
A39: 8. Everything else | B39: Tier 3. Daily rating offered only for goals you'd feel rather than measure.
A41: How the effect numbers were made, and how much to trust them
A42: Each is the typical published effect for the row's main number, divided by a typical person's normal night-to-night swing for that number (see the 'Numbers we can watch' sheet). Where the effect depends on the person (a hot sleeper, a snorer, someone with night bathroom trips), the 'where the estimate comes from' column says what number to use instead. These are working estimates from the literature as I know it, not a meta-analysis, and every one of them is a fair target for the team to challenge. The gate at 0.8 is a judgement call: at 0.8, seven nights a side gives roughly a one-in-three chance of a clear answer; at 1.2 it's better than even.
A44: 'What are you about to buy?' Free stand-in tests
A45: Sauna | B45: Hot bath or shower 1 to 2 hours before bed, 14 days. Same mechanism.
A46: Cold plunge tub | B46: Cold shower, 14 days. If HRV doesn't notice the shower, the tub won't change that.
A47: Eight Sleep or cooling pad | B47: Thermostat down 2 degrees plus a fan, 14 days.
...

Sheet Items
A1: # | B1: Key | C1: Item | D1: Do, buy, or environment | E1: Category | F1: Cost per month (USD) | G1: Cost per year (USD) | H1: Typical amount or how often | I1: What people usually take it for | J1: Can a wearable see it? | K1: Which number we'd watch | L1: Which way it should move | M1: How fast it acts and clears | N1: How we'd test it | O1: Can we run it this semester? | P1: Expected effect (in units of a normal night-to-night swing) | Q1: Where the effect estimate comes from | R1: Chance of a clear answer in two weeks | S1: Tier | T1: Tier name | U1: Tier after the effect gate (what the engine uses) | V1: Can we read it from their history? | W1: On-days: assigned or observed? | X1: Lowest dose worth testing (below this = day-one drop) | Y1: Evidence grade | Z1: What the studies actually found | AA1: Is there a known way it could work? | AB1: Why it's a day-one drop (Tier 2 only) | AC1: How the answer changes with the person's goal or situation | AD1: Follow-up question (trigger) | AE1: Question wording | AF1: Answer options | AG1: Rule that flips the tier (threshold) | AH1: Overlap group | AI1: Safety note (shown with the verdict) | AJ1: What the user reads on day one | AK1: Needs a fact-check? | AL1: What to check, and where to look
A2: 1 | B2: magnesium-any-form | C2: Magnesium (any form) | D2: buy | E2: supplement | F2: 22 | G2: =F2*12 -> 264 | H2: 200–400 mg elemental, evening | I2: sleep, relaxation, cramps | J2: yes | K2: Time to fall asleep; deep sleep | L2: fall asleep faster | M2: fast: acts and clears within hours | N2: 3 days on, 3 days off, for 14 days | O2: yes | P2: 0.3 | Q2: About 5 min faster to fall asleep in people who were low in magnesium; near zero in everyone else. Deep sleep does not move. | R2: low | S2: 1 | T2: Tested on you | U2: 3, effect too small | V2: yes, if they've been tagging it in Oura or WHOOP | W2: assign (we set the on and off days) | X2: ≥200 mg elemental (sleep trials used 320–500 mg) | Y2: B | Z2: Small trials found people fell asleep about 15 minutes faster, mostly older adults or people who were low in magnesium to begin with. The effect on deep sleep and other stages is small or absent. | AA2: yes | AC2: Goal sleep: Tier 1. Goal cramps or 'general': Tier 3. Dose under 200 mg elemental: Tier 2 (dose too low). | AD2: dose & form | AE2: Which form, and how much a day? | AF2: glycinate · citrate · malate · threonate · oxide · spray or oil · not sure; dose in mg elemental | AG2: form = oxide or spray → Tier 2 (form not absorbed). form = glycinate, citrate, malate, threonate AND dose under 200 mg elemental → Tier 2 (dose too low). Otherwise goal sleep → Tier 3 (effect too small, can run anyway); goal cramps or general → Tier 3. | AH2: sleep aids, magnesium | AI2: Loose stools at high doses. Kidney disease: ask a clinician first. | AJ2: Where it worked in trials, the change was a few minutes, mostly in people low in magnesium. That's about a third of one night's normal swing, so a two-week test would very likely come back inconclusive. We'll show you what the trials found and what it costs, and if you'd still like to run it, you can, knowing that going in. | AK2: no
A3: 2 | B3: magnesium-spray-oil-transdermal | C3: Magnesium spray / oil (transdermal) | D3: buy | E3: supplement | F3: 15 | G3: =F3*12 -> 180 | H3: nightly | I3: sleep, cramps | J3: yes | K3: Time to fall asleep | M3: fast: acts and clears within hours | N3: no experiment | O3: no | P3: 0 | Q3: Tier 2; not absorbed. | R3: not tested | S3: 2 | T3: No test needed | U3: 2 | V3: no | X3: no absorbed dose established | Y3: N | Z3: No controlled study has shown that magnesium gets through skin in a meaningful amount. The one small trial claiming it did wasn't blinded, meaning people knew what they were getting. | AA3: no | AB3: no way it could work | AC3: Always Tier 2. | AD3: none | AE3: (no question) | AF3: Routes on the item name alone. | AG3: Routes on the item name alone. | AJ3: There's no evidence magnesium gets through skin in a meaningful amount. If the ritual is part of your wind-down, that's real and it's yours. The $15 a month for the magnesium itself isn't doing anything. | AK3: yes | AL3: That no controlled study shows skin absorption. Look for: Gröber 2017 review of transdermal magnesium.
A4: 3 | B4: magnesium-l-threonate | C4: Magnesium L-threonate | D4: buy | E4: supplement | F4: 40 | G4: =F4*12 -> 480 | H4: 1–2 g product (~144 mg elemental) | I4: sleep, cognition | J4: yes | K4: Deep sleep; time to fall asleep | L4: improve | M4: fast: acts and clears within hours | N4: 3 days on, 3 days off, for 14 days | O4: yes | P4: 0.3 | Q4: One small seller-funded trial. | R4: low | S4: 1 | T4: Tested on you | U4: 3, effect too small | V4: yes, if they've been tagging it in Oura or WHOOP | W4: assign (we set the on and off days) | X4: ≥1 g product | Y4: C | Z4: One small trial, paid for by the seller, found a modest sleep improvement in adults. The claims about thinking and memory come from data in rats. | AA4: weak | AC4: Goal sleep: Tier 1. Goal cognition: Tier 3 (focus rating). | AD4: dose & form | AE4: Which form, and how much a day? | AF4: dose in g of product | AG4: dose under 1 g of product a day → Tier 2 (dose too low). Otherwise Tier 3 (effect too small, can run anyway). | AH4: magnesium | AJ4: The one trial found a modest change, and the company paid for it. That's about a third of one night's normal swing, so a two-week test would very likely come back inconclusive. We'll show you what the trials found and what it costs, and if you'd still like to run it, you can, knowing that going in. | AK4: yes | AL4: The one adult sleep trial and its funding. Look for: Hausenblas 2024 (Neurocentria-funded).
A5: 4 | B5: melatonin | C5: Melatonin | D5: buy | E5: supplement | F5: 10 | G5: =F5*12 -> 120 | H5: 0.3–5 mg, 30–60 min before bed | I5: time to fall asleep, jet lag | J5: yes | K5: Time to fall asleep | L5: fall asleep faster | M5: fast: acts and clears within hours | N5: 3 days on, 3 days off, for 14 days | O5: yes | P5: 0.8 | Q5: About 7 min faster to fall asleep against a 10-min swing, so 0.7 for most people. Use 1.2 if the person takes over 30 min to fall asleep or has a shifted schedule (that's who it works for). | R5: fair | S5: 1 | T5: Tested on you | U5: 1 | V5: yes, if they've been tagging it in Oura or WHOOP | W5: assign (we set the on and off days) | X5: 0.3 mg is already active; more is not better | Y5: B | Z5: Reviews that pool many trials say it helps people fall asleep about 7 minutes faster and sleep about 8 minutes longer. It works well for jet lag and shifted schedules, less well for ordinary trouble sleeping. Taking more than 1 mg adds grogginess, not effect. | AA5: yes | AC5: Tier 1. If dose > 5 mg, verdict adds the 'less is more' line. | AD5: dose & form | AE5: Which form, and how much a day? | AF5: 0.3 · 0.5 · 1 · 3 · 5 · 10 mg; gummy or tablet | AG5: No tier flip. dose over 1 mg → verdict adds the 'less is more' line. dose over 5 mg → safety note. | AH5: sleep aids | AI5: Gummy doses are often mislabeled. Ask a clinician before nightly long-term use, for teens, or in pregnancy. | AJ5: Testable. The interesting question isn't whether it works, it's whether you need it every night or only when your schedule shifts. | AK5: yes | AL5: 7 and 8 minute figures. Look for: Ferracioli-Oda 2013 meta-analysis.
A6: 5 | B6: l-theanine | C6: L-theanine | D6: buy | E6: supplement | F6: 16 | G6: =F6*12 -> 192 | H6: 100–400 mg | I6: sleep, calm, focus with caffeine | J6: partial | K6: Time to fall asleep; overnight HRV | L6: fall asleep faster / HRV up | M6: fast: acts and clears within hours | N6: 3 days on, 3 days off, for 14 days | O6: yes | P6: 0.2 | Q6: Measured sleep changes are small and inconsistent. | R6: low | S6: 1 | T6: Tested on you | U6: 3, effect too small | V6: yes, if they've been tagging it in Oura or WHOOP | W6: assign (we set the on and off days) | X6: ≥200 mg | Y6: C | Z6: Trials found people said they felt less stressed. Measured changes in sleep were small and inconsistent. The best evidence is for taking the edge off caffeine when you take the two together. | AA6: yes | AC6: Goal sleep: Tier 1. Goal calm/focus: Tier 3 (rating). Dose under 100 mg: Tier 2 (dose too low). | AD6: dose & form | AE6: Which form, and how much a day? | AF6: mg | AG6: dose under 100 mg → Tier 2 (dose too low). Otherwise Tier 3 (effect too small, can run anyway). | AH6: sleep aids | AJ6: The measured sleep changes in trials are small and inconsistent. That's about a fifth of one night's normal swing, so a two-week test would very likely come back inconclusive. We'll show you what the trials found and what it costs, and if you'd still like to run it, you can, knowing that going in. | AK6: no
A7: 6 | B7: glycine | C7: Glycine | D7: buy | E7: supplement | F7: 12 | G7: =F7*12 -> 144 | H7: 3 g before bed | I7: sleep quality | J7: yes | K7: Time to fall asleep; deep sleep | L7: improve | M7: fast: acts and clears within hours | N7: 3 days on, 3 days off, for 14 days | O7: yes | P7: 0.4 | Q7: Two tiny trials; a few minutes faster to fall asleep. | R7: low | S7: 1 | T7: Tested on you | U7: 3, effect too small | V7: yes, if they've been tagging it in Oura or WHOOP | W7: assign (we set the on and off days) | X7: ≥3 g | Y7: C | Z7: Two small Japanese trials, about 20 people each, found people fell asleep faster and felt less tired the next day on 3 g. Nothing bigger has been done since. | AA7: yes | AC7: Dose under 1 g: Tier 2 (dose too low). Otherwise Tier 1. | AD7: dose & form | AE7: Which form, and how much a day? | AF7: g | AG7: dose under 1 g → Tier 2 (dose too low). Otherwise Tier 3 (effect too small, can run anyway). | AH7: sleep aids | AJ7: Two tiny trials found a few minutes' difference. That's about two fifths of one night's normal swing, so a two-week test would very likely come back inconclusive. We'll show you what the trials found and what it costs, and if you'd still like to run it, you can, knowing that going in. | AK7: yes | AL7: The 3 g trials. Look for: Yamadera 2007; Inagawa 2006.
A8: 7 | B8: apigenin | C8: Apigenin | D8: buy | E8: supplement | F8: 20 | G8: =F8*12 -> 240 | H8: 50 mg | I8: sleep | J8: yes | K8: Time to fall asleep; deep sleep | L8: improve | M8: fast: acts and clears within hours | N8: 3 days on, 3 days off, for 14 days | O8: yes | P8: 0.1 | Q8: No human trial; nothing to expect. | R8: low | S8: 1 | T8: Tested on you | U8: 3, effect too small | V8: yes, if they've been tagging it in Oura or WHOOP | W8: assign (we set the on and off days) | X8: no human dose established | Y8: D | Z8: There has never been a human trial of apigenin on its own for sleep. It became popular because of one podcast protocol and some lab-dish work on brain receptors. | AA8: weak | AC8: Tier 1 (it's testable). Verdict notes the evidence is a podcast, not a trial. | AD8: overlap (automatic) | AE8: (no question) | AF8: Fires on its own when two or more items from the same overlap group are both in the inventory. The person is shown both and asked which one they'd keep. | AG8: Routes on the item name alone. | AH8: sleep aids | AJ8: There has never been a human trial, so there's no effect size to expect. That's about a tenth of one night's normal swing, so a two-week test would very likely come back inconclusive. We'll show you what the trials found and what it costs, and if you'd still like to run it, you can, knowing that going in. | AK8: no
A9: 8 | B9: ashwagandha-ksm-66-sensoril | C9: Ashwagandha (KSM-66 / Sensoril) | D9: buy | E9: supplement | F9: 19 | G9: =F9*12 -> 228 | H9: 300–600 mg root extract daily | I9: stress, sleep, cortisol | J9: partial | K9: Overnight HRV; time to fall asleep | L9: HRV up | M9: slow: builds up or clears over weeks | N9: 2 weeks on, 2 weeks off (not this semester) | O9: no | P9: 0.5 | Q9: Modest sleep and HRV changes after 6 to 8 weeks. Long blocks only. | R9: not in two weeks | S9: 1 | T9: Tested on you | U9: 1, queued (slow) | V9: no | W9: assign (we set the on and off days) | X9: ≥300 mg standardised extract | Y9: B | Z9: Several trials lasting 6 to 8 weeks found people said they felt less stressed and slept a bit better. The effect builds over weeks, not nights. | AA9: yes | AC9: Slow: long blocks only. v1: honest 'can't test in 14 days' plus evidence line. Dose under 250 mg: Tier 2 (dose too low). | AD9: dose & form | AE9: Which form, and how much a day? | AF9: KSM-66 · Sensoril · other extract · plain root powder · not sure; dose in mg | AG9: form = plain root powder under 1 g, or extract under 250 mg → Tier 2 (dose too low). Otherwise Tier 1, queued (slow). | AI9: Rare liver injury reports; can raise thyroid hormone. Avoid in pregnancy. Stop and ask a clinician if you get nausea or dark urine. | AJ9: This one works slowly, so a two-week on/off test would be unfair to it. We'll tell you what the trials found, and queue it for a longer test when we can run one. | AK9: yes | AL9: Liver injury and thyroid reports. Look for: LiverTox (NIH) entry on ashwagandha.
A10: 9 | B10: valerian | C10: Valerian | D10: buy | E10: supplement | F10: 12 | G10: =F10*12 -> 144 | H10: 300–600 mg | I10: sleep | J10: yes | K10: Time to fall asleep | L10: fall asleep faster | M10: fast: acts and clears within hours | N10: 3 days on, 3 days off, for 14 days | O10: yes | P10: 0.2 | Q10: Measured sleep mostly unchanged in trials. | R10: low | S10: 1 | T10: Tested on you | U10: 3, effect too small | V10: yes, if they've been tagging it in Oura or WHOOP | W10: assign (we set the on and off days) | X10: ≥300 mg | Y10: C | Z10: Trials are mixed. People sometimes say they slept better, but their measured sleep mostly didn't change. | AA10: weak | AC10: Tier 1. | AD10: dose & form | AE10: Which form, and how much a day? | AF10: mg | AG10: dose under 300 mg → Tier 2 (dose too low). Otherwise Tier 3 (effect too small, can run anyway). | AH10: sleep aids | AJ10: In trials, people felt they slept better while their measured sleep stayed the same. That's about a fifth of one night's normal swing, so a two-week test would very likely come back inconclusive. We'll show you what the trials found and what it costs, and if you'd still like to run it, you can, knowing that going in. | AK10: no
A11: 10 | B11: chamomile-tea | C11: Chamomile tea | D11: buy | E11: food/drink | F11: 8 | G11: =F11*12 -> 96 | H11: 1 cup nightly | I11: sleep, wind-down | J11: yes | K11: Time to fall asleep | L11: fall asleep faster | M11: fast: acts and clears within hours | N11: 3 days on, 3 days off, for 14 days | O11: yes | P11: 0.2 | Q11: Measured sleep unchanged; people feel calmer. | R11: low | S11: 1 | T11: Tested on you | U11: 3, effect too small | V11: yes, if they've been tagging it in Oura or WHOOP | W11: assign (we set the on and off days) | X11: no dose rule | Y11: C | Z11: Small trials found people said they slept slightly better, but their measured sleep didn't reliably change. The warm drink and the routine may be most of what's working. | AA11: weak | AC11: Tier 1. Cheap and enjoyed: verdict says keep regardless of result. | AD11: overlap (automatic) | AE11: (no question) | AF11: Fires on its own when two or more items from the same overlap group are both in the inventory. The person is shown both and asked which one they'd keep. | AG11: Routes on the item name alone. | AH11: sleep aids | AJ11: People feel calmer; the sleep numbers don't change. That's about a fifth of one night's normal swing, so a two-week test would very likely come back inconclusive. We'll show you what the trials found and what it costs, and if you'd still like to run it, you can, knowing that going in. | AK11: no
A12: 11 | B12: sleep-tea-blend-valerian-passionflower-lemon-balm | C12: Sleep tea blend (valerian, passionflower, lemon balm) | D12: buy | E12: food/drink | F12: 17 | G12: =F12*12 -> 204 | H12: nightly | I12: sleep | J12: yes | K12: Time to fall asleep | L12: fall asleep faster | M12: fast: acts and clears within hours | N12: 3 days on, 3 days off, for 14 days | O12: yes | P12: 0.2 | Q12: As the individual herbs. | R12: low | S12: 1 | T12: Tested on you | U12: 3, effect too small | V12: yes, if they've been tagging it in Oura or WHOOP | W12: assign (we set the on and off days) | X12: no dose rule | Y12: C | Z12: Each herb has small, mixed trials. Blends are untested as products. | AA12: weak | AC12: Tier 1. | AD12: overlap (automatic) | AE12: (no question) | AF12: Fires on its own when two or more items from the same overlap group are both in the inventory. The person is shown both and asked which one they'd keep. | AG12: Routes on the item name alone. | AH12: sleep aids | AJ12: Each herb has small trials, and none moved the numbers much. That's about a fifth of one night's normal swing, so a two-week test would very likely come back inconclusive. We'll show you what the trials found and what it costs, and if you'd still like to run it, you can, knowing that going in. | AK12: no
A13: 12 | B13: tart-cherry-juice-extract | C13: Tart cherry juice / extract | D13: buy | E13: supplement | F13: 30 | G13: =F13*12 -> 360 | H13: 240 ml twice daily or 480 mg extract | I13: sleep, recovery | J13: yes | K13: Total sleep | L13: up | M13: fast: acts and clears within hours | N13: 3 days on, 3 days off, for 14 days | O13: yes | P13: 0.4 | Q13: Tiny trials claim 30 to 80 min; a realistic guess after shrinking for tiny-study inflation is under half a swing. | R13: low | S13: 1 | T13: Tested on you | U13: 3, effect too small | V13: yes, if they've been tagging it in Oura or WHOOP | W13: assign (we set the on and off days) | X13: ≥240 ml juice or 480 mg extract | Y13: C | Z13: Two tiny trials, 8 to 20 people, reported 30 to 80 extra minutes of sleep. No bigger study has repeated the result. It contains a small amount of natural melatonin. | AA13: yes | AC13: Tier 1. | AD13: dose & form | AE13: Which form, and how much a day? | AF13: juice (ml a day) · extract (mg) | AG13: juice under 240 ml a day, or extract under 480 mg → Tier 2 (dose too low). Otherwise Tier 3 (effect too small, can run anyway). | AI13: About 25 g sugar per serving of juice. | AJ13: The tiny trials claimed a lot; the realistic expectation is under half a night's swing. That's about two fifths of one night's normal swing, so a two-week test would very likely come back inconclusive. We'll show you what the trials found and what it costs, and if you'd still like to run it, you can, knowing that going in. | AK13: yes | AL13: Trial sizes. Look for: Howatson 2012 (n=20); Losso 2018 (n=8).
A14: 13 | B14: cbd | C14: CBD | D14: buy | E14: supplement | F14: 45 | G14: =F14*12 -> 540 | H14: 10–50 mg gummies or oil | I14: sleep, anxiety | J14: yes | K14: Time to fall asleep; time awake during the night | L14: improve | M14: fast: acts and clears within hours | N14: 3 days on, 3 days off, for 14 days | O14: yes | P14: 0.3 | Q14: Mixed trials at doses higher than most products. | R14: low | S14: 1 | T14: Tested on you | U14: 3, effect too small | V14: yes, if they've been tagging it in Oura or WHOOP | W14: assign (we set the on and off days) | X14: ≥25 mg (trials used 25–160 mg and more) | Y14: C | Z14: The sleep trials used much higher doses than most gummies contain, and even then the results were mixed. The dose on the label is often wrong. | AA14: weak | AC14: Dose under 25 mg: Tier 2 (dose too low). Otherwise Tier 1. | AD14: dose & form | AE14: Which form, and how much a day? | AF14: mg per serving; gummy · oil · capsule | AG14: dose under 25 mg → Tier 2 (dose too low). Otherwise Tier 3 (effect too small, can run anyway). Any medication → Protected. | AH14: sleep aids | AI14: Interacts with some medications (blood thinners, some antidepressants). Check. | AJ14: At the doses in most products, the trials found little. That's about a third of one night's normal swing, so a two-week test would very likely come back inconclusive. We'll show you what the trials found and what it costs, and if you'd still like to run it, you can, knowing that going in. | AK14: yes | AL14: Dose gap between products and trials. Look for: Shannon 2019 (25 to 175 mg); product testing reports on mislabelling.
A15: 14 | B15: thc-cannabis-for-sleep | C15: THC / cannabis for sleep | D15: buy | E15: supplement | F15: 60 | G15: =F15*12 -> 720 | H15: nightly | I15: sleep | J15: yes | K15: Time to fall asleep; REM | L15: fall asleep faster / REM down | M15: fast: acts and clears within hours | N15: stop once, wait a week, then compare | O15: no | P15: 1.2 | Q15: 15 min faster to fall asleep and a clear REM drop, but the catch-up effect on stopping breaks the 3/3 test. Special design only. | R15: not in two weeks | S15: 1 | T15: Tested on you | U15: 1, queued (special design) | V15: yes, if they've been tagging it in Oura or WHOOP | W15: observe only (never assign an on-day) | X15: no dose rule | Y15: C | Z15: It helps you fall asleep faster in the short term and cuts down REM sleep. When you stop, you get several nights of REM catch-up and worse sleep. That catch-up effect makes a simple on/off test give the wrong answer. | AA15: yes | AC15: Not alternation-compatible (rebound). v1: report evidence only. Later: single switch with 7-night washout. | AD15: nights a week | AE15: How many nights a week, usually? | AF15: 0 · 1 to 2 · 3 to 4 · 5 or more. Asked plainly, no comment, no follow-up. | AG15: Routes on the item name alone. | AI15: Legal status varies. Nightly use builds tolerance; withdrawal insomnia is real and temporary. | AJ15: We can't run this as a 3-on/3-off test, because the off nights after nightly use are worse for everyone, and that would make the cannabis look like it 'works'. That would be a dishonest result, so we won't give you one. | AK15: yes | AL15: REM suppression and rebound. Look for: Babson 2017 review.
A16: 15 | B16: kava | C16: Kava | D16: buy | E16: supplement | F16: 30 | G16: =F16*12 -> 360 | H16: tea or capsule, evening | I16: anxiety, sleep | J16: yes | K16: Time to fall asleep | L16: fall asleep faster | M16: fast: acts and clears within hours | N16: 3 days on, 3 days off, for 14 days | O16: yes | P16: 0.4 | Q16: Anxiety evidence is decent; sleep evidence is thin. | R16: low | S16: 1 | T16: Tested on you | U16: 3, effect too small | V16: yes, if they've been tagging it in Oura or WHOOP | W16: assign (we set the on and off days) | X16: no dose rule | Y16: B | Z16: Decent evidence from proper trials that it helps with anxiety in the short term. The evidence for sleep is thin. | AA16: yes | AC16: Goal sleep: Tier 1. Goal anxiety: Tier 3 (mood rating). | AD16: overlap (automatic) | AE16: (no question) | AF16: Fires on its own when two or more items from the same overlap group are both in the inventory. The person is shown both and asked which one they'd keep. | AG16: Any alcohol most nights, or liver condition → safety note, Tier 3. | AH16: sleep aids | AI16: Liver injury has been reported. Avoid with alcohol or liver conditions. | AJ16: Decent for anxiety; thin for sleep. That's about two fifths of one night's normal swing, so a two-week test would very likely come back inconclusive. We'll show you what the trials found and what it costs, and if you'd still like to run it, you can, knowing that going in. | AK16: yes | AL16: Liver warnings. Look for: FDA 2002 consumer advisory; LiverTox.
A17: 16 | B17: passionflower | C17: Passionflower | D17: buy | E17: supplement | F17: 12 | G17: =F17*12 -> 144 | H17: capsule or tea | I17: sleep, anxiety | J17: yes | K17: Time to fall asleep | L17: fall asleep faster | M17: fast: acts and clears within hours | N17: 3 days on, 3 days off, for 14 days | O17: yes | P17: 0.2 | Q17: One small trial of tea. | R17: low | S17: 1 | T17: Tested on you | U17: 3, effect too small | V17: yes, if they've been tagging it in Oura or WHOOP | W17: assign (we set the on and off days) | X17: no dose rule | Y17: C | Z17: One small trial of the tea found people said they slept slightly better. | AA17: weak | AC17: Tier 1. | AD17: overlap (automatic) | AE17: (no question) | AF17: Fires on its own when two or more items from the same overlap group are both in the inventory. The person is shown both and asked which one they'd keep. | AG17: Routes on the item name alone. | AH17: sleep aids | AJ17: One small trial of the tea found a small difference in how people felt. That's about a fifth of one night's normal swing, so a two-week test would very likely come back inconclusive. We'll show you what the trials found and what it costs, and if you'd still like to run it, you can, knowing that going in. | AK17: no
A18: 17 | B18: lemon-balm | C18: Lemon balm | D18: buy | E18: supplement | F18: 12 | G18: =F18*12 -> 144 | H18: capsule or tea | I18: sleep, calm | J18: yes | K18: Time to fall asleep | L18: fall asleep faster | M18: fast: acts and clears within hours | N18: 3 days on, 3 days off, for 14 days | O18: yes | P18: 0.2 | Q18: Small trials, mostly how people felt. | R18: low | S18: 1 | T18: Tested on you | U18: 3, effect too small | V18: yes, if they've been tagging it in Oura or WHOOP | W18: assign (we set the on and off days) | X18: no dose rule | Y18: C | Z18: Small trials, mostly people saying they felt calmer. | AA18: weak | AC18: Tier 1. | AD18: overlap (automatic) | AE18: (no question) | AF18: Fires on its own when two or more items from the same overlap group are both in the inventory. The person is shown both and asked which one they'd keep. | AG18: Routes on the item name alone. | AH18: sleep aids | AJ18: Small trials, mostly about how people felt. That's about a fifth of one night's normal swing, so a two-week test would very likely come back inconclusive. We'll show you what the trials found and what it costs, and if you'd still like to run it, you can, knowing that going in. | AK18: no
A19: 18 | B19: 5-htp | C19: 5-HTP | D19: buy | E19: supplement | F19: 15 | G19: =F19*12 -> 180 | H19: 50–200 mg | I19: sleep, mood | J19: yes | K19: Time to fall asleep; REM | L19: improve | M19: fast: acts and clears within hours | N19: 3 days on, 3 days off, for 14 days | O19: yes | P19: 0.2 | Q19: Small trials. | R19: low | S19: 1 | T19: Tested on you | U19: 3, effect too small | V19: yes, if they've been tagging it in Oura or WHOOP | W19: assign (we set the on and off days) | X19: ≥100 mg | Y19: C | Z19: Small trials. The evidence for mood is a little stronger than for sleep. | AA19: yes | AC19: Goal sleep: Tier 1. Goal mood: Tier 3 (rating). On any antidepressant: Protected. | AD19: dose & form | AE19: Which form, and how much a day? | AF19: mg | AG19: dose under 100 mg → Tier 2 (dose too low). On an antidepressant → Protected. | AH19: sleep aids | AI19: Do not combine with antidepressants (serotonin syndrome risk). | AJ19: The sleep trials are small. That's about a fifth of one night's normal swing, so a two-week test would very likely come back inconclusive. We'll show you what the trials found and what it costs, and if you'd still like to run it, you can, knowing that going in. | AK19: no
A20: 19 | B20: gaba-oral | C20: GABA (oral) | D20: buy | E20: supplement | F20: 15 | G20: =F20*12 -> 180 | H20: 500–750 mg | I20: sleep, calm | J20: yes | K20: Time to fall asleep | M20: fast: acts and clears within hours | N20: no experiment | O20: no | P20: 0 | Q20: Tier 2; can't reach the brain. | R20: not tested | S20: 2 | T20: No test needed | U20: 2 | V20: no | X20: no dose rule | Y20: D | Z20: Swallowed GABA mostly can't get past the barrier that protects the brain. The small trials that exist were paid for by the sellers and don't agree with each other. | AA20: no | AB20: no way it could work | AC20: Tier 2. | AD20: none | AE20: (no question) | AF20: Routes on the item name alone. | AG20: Routes on the item name alone. | AJ20: The reason this probably isn't working is that swallowed GABA mostly can't reach the brain. That's chemistry, not you. | AK20: yes | AL20: Barrier claim and seller funding of the trials. Look for: Boonstra 2015 review of oral GABA.
A21: 20 | B21: lavender-oil-oral-silexan | C21: Lavender oil, oral (Silexan) | D21: buy | E21: supplement | F21: 25 | G21: =F21*12 -> 300 | H21: 80 mg | I21: anxiety, sleep | J21: partial | K21: Time to fall asleep | L21: fall asleep faster | M21: fast: acts and clears within hours | N21: 3 days on, 3 days off, for 14 days | O21: yes | P21: 0.4 | Q21: Sleep improves alongside anxiety; modest in the numbers. | R21: low | S21: 1 | T21: Tested on you | U21: 3, effect too small | V21: yes, if they've been tagging it in Oura or WHOOP | W21: assign (we set the on and off days) | X21: 80 mg | Y21: B | Z21: Decent trials for anxiety. People's sleep improved alongside their anxiety. | AA21: yes | AC21: Goal sleep: Tier 1. Goal anxiety: Tier 3 (rating). | AD21: dose & form | AE21: Which form, and how much a day? | AF21: Silexan 80 mg · other oral lavender · essential oil | AG21: form = anything other than Silexan 80 mg (e.g. a generic lavender capsule or essential oil taken by mouth) → Tier 2 (form not absorbed) with a safety note about swallowing essential oils. | AH21: sleep aids | AJ21: Sleep improves a little alongside anxiety. That's about two fifths of one night's normal swing, so a two-week test would very likely come back inconclusive. We'll show you what the trials found and what it costs, and if you'd still like to run it, you can, knowing that going in. | AK21: no
A22: 21 | B22: sleep-gummies-blend | C22: Sleep gummies (blend) | D22: buy | E22: supplement | F22: 20 | G22: =F22*12 -> 240 | H22: nightly | I22: sleep | J22: yes | K22: Time to fall asleep | L22: fall asleep faster | M22: fast: acts and clears within hours | N22: 3 days on, 3 days off, for 14 days | O22: yes | P22: 0.6 | Q22: The melatonin in it, usually at a higher-than-useful dose. | R22: low | S22: 1 | T22: Tested on you | U22: 3, effect too small | V22: yes, if they've been tagging it in Oura or WHOOP | W22: assign (we set the on and off days) | X22: depends on melatonin content | Y22: B | Z22: Usually melatonin plus tiny amounts of herbs. The melatonin is what's working. The dose on gummy labels is often wrong. | AA22: yes | AC22: Tier 1. Verdict notes plain melatonin at 0.5 mg is a third of the price. | AD22: dose & form | AE22: Which form, and how much a day? | AF22: melatonin mg per gummy, from the label | AG22: melatonin content over 3 mg → verdict adds the 'less is more' line. Contains no melatonin → route as the herb blend (Tier 3, effect too small). | AH22: sleep aids | AJ22: It's the melatonin doing the work, and for most people that's a few minutes. That's about three fifths of one night's normal swing, so a two-week test would very likely come back inconclusive. We'll show you what the trials found and what it costs, and if you'd still like to run it, you can, knowing that going in. | AK22: yes | AL22: Gummy mislabelling. Look for: Cohen 2023, JAMA (melatonin gummies).
A23: 22 | B23: zma | C23: ZMA | D23: buy | E23: supplement | F23: 20 | G23: =F23*12 -> 240 | H23: zinc 30 mg, magnesium 450 mg, B6 | I23: sleep, testosterone, recovery | J23: yes | K23: Deep sleep | L23: up | M23: fast: acts and clears within hours | N23: 3 days on, 3 days off, for 14 days | O23: yes | P23: 0.3 | Q23: As magnesium. | R23: low | S23: 1 | T23: Tested on you | U23: 3, effect too small | V23: yes, if they've been tagging it in Oura or WHOOP | W23: assign (we set the on and off days) | X23: no dose rule | Y23: N | Z23: The testosterone claim was never repeated by other researchers. Any sleep effect is the magnesium. | AA23: weak | AC23: Goal testosterone: Tier 2 (tested, found nothing). Goal sleep: Tier 1 as magnesium. | AD23: overlap (automatic) | AE23: (no question) | AF23: Fires on its own when two or more items from the same overlap group are both in the inventory. The person is shown both and asked which one they'd keep. | AG23: Routes on the item name alone. | AH23: magnesium | AJ23: The magnesium part might do a little; the rest does nothing measurable. That's about a third of one night's normal swing, so a two-week test would very likely come back inconclusive. We'll show you what the trials found and what it costs, and if you'd still like to run it, you can, knowing that going in. | AK23: no
A24: 23 | B24: vitamin-d3 | C24: Vitamin D3 | D24: buy | E24: supplement | F24: 8 | G24: =F24*12 -> 96 | H24: 1,000–5,000 IU | I24: energy, immunity, mood, bone | J24: no | M24: slow: builds up or clears over weeks | N24: no experiment | O24: no | R24: not tested | S24: 3 | T24: Can't measure it | U24: 3 | V24: no | X24: no dose rule | Y24: B | Z24: Clearly useful if you're low in it, which is common in winter and for people with darker skin living far from the equator. In people whose levels are normal, large trials found little benefit for mood, energy or catching fewer colds. | AA24: yes | AC24: Source = doctor/blood test: Protected. Otherwise Tier 3 with a nudge to get a level. | AD24: dose & form | AE24: Which form, and how much a day? | AF24: IU a day | AG24: No tier flip on dose. dose over 10,000 IU a day → safety note. Source = doctor or blood test → Protected. | AH24: daily multivitamin | AI24: Very high doses (over 10,000 IU/day) long term can cause harm. | AJ24: We can't see this in your data, and we won't tell you to drop it, because if you're low it matters. A blood level costs about $30 and answers this properly. | AK24: yes | AL24: Large trials in non-deficient people. Look for: VITAL (Manson 2019); D-Health (Neale 2022).
A25: 24 | B25: vitamin-b12 | C25: Vitamin B12 | D25: buy | E25: supplement | F25: 8 | G25: =F25*12 -> 96 | H25: 500–1,000 mcg | I25: energy | J25: no | M25: slow: builds up or clears over weeks | N25: no experiment | O25: no | R25: not tested | S25: 2 | T25: No test needed | U25: 2 | V25: no | X25: no dose rule | Y25: N | Z25: In people who aren't low in it, B12 does nothing for energy, and that's been tested several times. Vegans, vegetarians, people over 60, and people on metformin or stomach-acid reducers are often low. | AA25: weak | AB25: tested, found nothing | AC25: Source = doctor/blood test, or user is vegan/vegetarian/60+: Tier 3 with 'get a level'. Otherwise Tier 2 (tested, found nothing). | AD25: overlap (automatic) | AE25: (no question) | AF25: Fires on its own when two or more items from the same overlap group are both in the inventory. The person is shown both and asked which one they'd keep. | AG25: Route on source and diet, not dose: vegan, vegetarian, over 60, on metformin or acid reducers, or doctor-sourced → Tier 3 'get a level'. Otherwise Tier 2 (tested, found nothing). | AH25: daily multivitamin | AJ25: If you eat meat and you're under 60, the energy you're hoping for isn't in this bottle; trials in people with normal levels are flat. If you're vegan or over 60, ignore that and get a level first. | AK25: yes | AL25: That trials in non-deficient people show no energy effect. Look for: Cochrane / systematic reviews of B12 supplementation in non-deficient adults.
A26: 25 | B26: b-complex | C26: B-complex | D26: buy | E26: supplement | F26: 10 | G26: =F26*12 -> 120 | H26: daily | I26: energy, stress | J26: no | M26: slow: builds up or clears over weeks | N26: no experiment | O26: no | R26: not tested | S26: 2 | T26: No test needed | U26: 2 | V26: no | X26: no dose rule | Y26: N | Z26: Same as B12: no effect on energy unless you're low in it. | AA26: weak | AB26: tested, found nothing | AC26: As B12. | AD26: overlap (automatic) | AE26: (no question) | AF26: Fires on its own when two or more items from the same overlap group are both in the inventory. The person is shown both and asked which one they'd keep. | AG26: Routes on the item name alone. | AH26: daily multivitamin | AJ26: Same as B12: without a deficiency, this isn't where energy comes from. | AK26: yes | AL26: Same as B12.
A27: 26 | B27: iron | C27: Iron | D27: buy | E27: supplement | F27: 8 | G27: =F27*12 -> 96 | H27: 18–65 mg | I27: energy, fatigue | J27: no | M27: slow: builds up or clears over weeks | N27: no experiment | O27: no | R27: not tested | S27: P | T27: Protected | U27: P | V27: no | X27: no dose rule | Y27: A | Z27: Life-changing if you're low in iron, which is common in women who menstruate and in endurance athletes. Harmful to take if you're not. | AA27: yes | AC27: Always Protected. Never routed to Tier 2. | AD27: none | AE27: (no question) | AF27: Routes on the item name alone. | AG27: Routes on the item name alone. | AI27: Iron without a confirmed low ferritin can cause harm. This needs a blood test, not an app. | AJ27: We don't touch iron. It's the one supplement that's either exactly what you need or something you shouldn't take, and only a ferritin test can say which. | AK27: yes | AL27: Harm from unneeded iron. Look for: NIH ODS iron fact sheet.
A28: 27 | B28: multivitamin | C28: Multivitamin | D28: buy | E28: supplement | F28: 15 | G28: =F28*12 -> 180 | H28: daily | I28: general health | J28: no | M28: slow: builds up or clears over weeks | N28: no experiment | O28: no | R28: not tested | S28: 3 | T28: Can't measure it | U28: 3 | V28: no | X28: no dose rule | Y28: C | Z28: Large trials in well-nourished adults show no effect on heart disease, cancer or mortality. Possibly a small cognitive benefit in older adults. | AA28: weak | AC28: Tier 3 (untestable). Verdict shows cost and evidence, no push either way. | AD28: overlap (automatic) | AE28: (no question) | AF28: Fires on its own when two or more items from the same overlap group are both in the inventory. The person is shown both and asked which one they'd keep. | AG28: Routes on the item name alone. | AH28: daily multivitamin | AJ28: Think of it as insurance. The big trials say it doesn't change much for people who eat reasonably well, and it also doesn't do any harm. Keep it or don't; either is a fine answer. | AK28: no
A29: 28 | B29: omega-3-fish-oil | C29: Omega-3 fish oil | D29: buy | E29: supplement | F29: 20 | G29: =F29*12 -> 240 | H29: 1–2 g EPA+DHA | I29: heart, mood, inflammation, joints | J29: no | M29: slow: builds up or clears over weeks | N29: no experiment | O29: no | R29: not tested | S29: 3 | T29: Can't measure it | U29: 3 | V29: no | X29: ≥1 g EPA+DHA combined (many capsules are 300 mg) | Y29: B | Z29: A modest benefit for blood fats, and possibly for mood, at 1 g a day and above. Most of the trials that found a benefit were in people who don't eat fish. | AA29: yes | AC29: EPA+DHA under 500 mg/day: Tier 2 (dose too low). Otherwise Tier 3. Source = doctor: Protected. | AD29: dose & form | AE29: Which form, and how much a day? | AF29: EPA + DHA in mg per capsule (back of the bottle), capsules a day | AG29: EPA + DHA combined under 500 mg a day → Tier 2 (dose too low). 500 mg to 1 g → Tier 3 with a 'below the studied dose' note. 1 g or more → Tier 3. | AH29: omega-3 | AI29: Blood thinners: check with prescriber. | AJ29: Check the back of the bottle for EPA + DHA, not 'fish oil'. Under 500 mg combined is a dose the trials never found anything at. At 1 g or more we can't see it in your data, but the evidence is decent. | AK29: yes | AL29: 1 g EPA+DHA threshold. Look for: AHA advisory; typical capsule contents.
A30: 29 | B30: krill-oil | C30: Krill oil | D30: buy | E30: supplement | F30: 30 | G30: =F30*12 -> 360 | H30: 500 mg | I30: heart, joints | J30: no | M30: slow: builds up or clears over weeks | N30: no experiment | O30: no | R30: not tested | S30: 2 | T30: No test needed | U30: 2 | V30: no | X30: ≥1 g EPA+DHA | Y30: B | Z30: The same omega-3 fats as fish oil, at a much smaller dose and several times the price. | AA30: yes | AB30: dose too low | AC30: Tier 2 (dose too low) unless taking 3+ capsules. | AD30: dose & form | AE30: Which form, and how much a day? | AF30: capsules a day; EPA + DHA per capsule | AG30: EPA + DHA under 1 g a day → Tier 2 (dose too low). Almost every krill product fires this at label dose. | AH30: omega-3 | AJ30: This is fish oil at a smaller dose and a higher price. If omega-3 is the goal, plain fish oil at 1 g EPA+DHA gets you what the trials used, for less. | AK30: yes | AL30: Typical EPA+DHA per capsule (about 100 to 150 mg) versus fish oil trial doses. Check three best-selling labels.
A31: 30 | B31: flaxseed-oil-as-omega-3 | C31: Flaxseed oil (as omega-3) | D31: buy | E31: supplement | F31: 12 | G31: =F31*12 -> 144 | H31: 1 tbsp | I31: omega-3, heart | J31: no | M31: slow: builds up or clears over weeks | N31: no experiment | O31: no | R31: not tested | S31: 2 | T31: No test needed | U31: 2 | V31: no | X31: no dose rule | Y31: N | Z31: Conversion of plant ALA to EPA/DHA is under 10%. Doesn't raise blood levels the way fish oil does. | AA31: weak | AB31: form not absorbed | AC31: Goal omega-3: Tier 2 (form not absorbed). As a food, fine. | AD31: overlap (automatic) | AE31: (no question) | AF31: Fires on its own when two or more items from the same overlap group are both in the inventory. The person is shown both and asked which one they'd keep. | AG31: Routes on the item name alone. | AH31: omega-3 | AJ31: Your body converts very little of this into the omega-3s fish oil provides. Fine as a food, not as a substitute. | AK31: yes | AL31: ALA to EPA/DHA conversion under 10%. Look for: Burdge & Calder 2005.
A32: 31 | B32: creatine-monohydrate | C32: Creatine monohydrate | D32: buy | E32: supplement | F32: 14 | G32: =F32*12 -> 168 | H32: 3–5 g daily | I32: strength, cognition, energy | J32: no | M32: slow: builds up or clears over weeks | N32: no experiment | O32: no | R32: not tested | S32: 3 | T32: Can't measure it | U32: 3 | V32: no | X32: ≥3 g/day | Y32: A | Z32: One of the best-supported supplements there is for strength and muscle in people who train. There's growing evidence it helps thinking when you're short on sleep. | AA32: yes | AC32: Dose under 2 g: Tier 2 (dose too low). Otherwise Tier 3 with 'strong evidence, keep if you lift'. Never Tier 1: saturation takes weeks, so alternation is invalid. | AD32: dose & form | AE32: Which form, and how much a day? | AF32: monohydrate · HCl · buffered · blend; g a day | AG32: dose under 2 g a day → Tier 2 (dose too low). form = HCl, buffered, or 'creatine blend' → verdict notes monohydrate is the studied form. Otherwise Tier 3 keep. | AI32: Take with water; a small water-weight gain is normal. Fine for kidneys in healthy adults. | AJ32: We can't see this in sleep or HRV, and that's fine, because the evidence here is strong. If you lift, keep it. If you don't, it's mostly doing nothing. | AK32: yes | AL32: 3 g minimum. Look for: ISSN position stand (Kreider 2017).
A33: 32 | B33: protein-powder | C33: Protein powder | D33: buy | E33: supplement | F33: 40 | G33: =F33*12 -> 480 | H33: 1–2 scoops | I33: muscle, satiety | J33: no | M33: slow: builds up or clears over weeks | N33: no experiment | O33: no | R33: not tested | S33: 3 | T33: Can't measure it | U33: 3 | V33: no | X33: no dose rule | Y33: A | Z33: It's food. Useful if you don't get enough protein from meals, irrelevant if you do. | AA33: yes | AC33: Tier 3 (food). Verdict shows cost. | AD33: none | AE33: (no question) | AF33: Routes on the item name alone. | AG33: No flip. | AJ33: This is food, not a supplement, so there's no verdict to give. If it helps you hit protein, keep it. If you already eat enough, it's an expensive way to buy calories. | AK33: no
A34: 33 | B34: bcaas | C34: BCAAs | D34: buy | E34: supplement | F34: 25 | G34: =F34*12 -> 300 | H34: 5–10 g | I34: muscle, recovery | J34: no | M34: slow: builds up or clears over weeks | N34: no experiment | O34: no | R34: not tested | S34: 2 | T34: No test needed | U34: 2 | V34: no | X34: no dose rule | Y34: N | Z34: If you eat enough protein, BCAAs add nothing, and that's been tested several times. They're already in the protein you eat. | AA34: weak | AB34: tested, found nothing | AC34: Tier 2 (tested, found nothing). | AD34: none | AE34: (no question) | AF34: Routes on the item name alone. | AG34: Routes on the item name alone. | AJ34: These are already in every protein source you eat. Trials in people eating enough protein show nothing extra. Easy $25 back. | AK34: yes | AL34: That BCAAs add nothing with adequate protein. Look for: Wolfe 2017 JISSN review.
A35: 34 | B35: glutamine | C35: Glutamine | D35: buy | E35: supplement | F35: 20 | G35: =F35*12 -> 240 | H35: 5 g | I35: gut, recovery | J35: no | M35: slow: builds up or clears over weeks | N35: no experiment | O35: no | R35: not tested | S35: 2 | T35: No test needed | U35: 2 | V35: no | X35: no dose rule | Y35: N | Z35: Found nothing for recovery in healthy adults. The gut evidence is from hospital patients only. | AA35: weak | AB35: tested, found nothing | AC35: Goal gut with a diagnosed condition: Protected. Otherwise Tier 2. | AD35: none | AE35: (no question) | AF35: Routes on the item name alone. | AG35: Routes on the item name alone. | AJ35: Useful in hospitals, not in healthy people. This one can go. | AK35: yes | AL35: No recovery benefit in healthy adults. Look for: Gleeson 2008 review.
A36: 35 | B36: beta-alanine | C36: Beta-alanine | D36: buy | E36: supplement | F36: 20 | G36: =F36*12 -> 240 | H36: 3–6 g | I36: endurance, performance | J36: no | M36: slow: builds up or clears over weeks | N36: no experiment | O36: no | R36: not tested | S36: 3 | T36: Can't measure it | U36: 3 | V36: no | X36: ≥3 g | Y36: A | Z36: Reliably helps with hard efforts lasting 1 to 4 minutes. Does nothing for longer or shorter efforts. The tingling it causes is harmless. | AA36: yes | AC36: Tier 3: keep for rowing / 800 m / CrossFit-type efforts, otherwise verdict says it's not for your training. | AD36: dose & form | AE36: Which form, and how much a day? | AF36: g a day | AG36: dose under 2 g a day → Tier 2 (dose too low). Otherwise Tier 3, with the 1-to-4-minute note. | AJ36: Works, but only for hard efforts of one to four minutes. If that's your sport, keep it. If you run long or lift heavy, it isn't doing anything for you. | AK36: no
A37: 36 | B37: pre-workout | C37: Pre-workout | D37: buy | E37: supplement | F37: 35 | G37: =F37*12 -> 420 | H37: 1 scoop (150–300 mg caffeine) | I37: energy, performance | J37: yes | K37: Time to fall asleep; total sleep | L37: worse if late | M37: fast: acts and clears within hours | N37: 3 days on, 3 days off, for 14 days | O37: yes | P37: 0.9 | Q37: As caffeine after 2pm, if taken after 1pm. | R37: fair | S37: 1 | T37: Tested on you | U37: 1 | V37: yes, if they've been tagging it in Oura or WHOOP | W37: assign (we set the on and off days) | X37: no dose rule | Y37: B | Z37: The caffeine in it works. Most of the other ingredients are in amounts too small to matter. Taken after 2pm, it costs you sleep. | AA37: yes | AC37: Used after 1pm: Tier 1 as caffeine timing. Otherwise Tier 3. | AD37: overlap (automatic) | AE37: (no question) | AF37: Fires on its own when two or more items from the same overlap group are both in the inventory. The person is shown both and asked which one they'd keep. | AG37: Routes on the item name alone. | AH37: caffeine before training | AJ37: If you take this after lunch, it's a caffeine-timing experiment, and one of the most reliable ones we run. | AK37: no
A38: 37 | B38: electrolytes-lmnt-etc | C38: Electrolytes (LMNT etc.) | D38: buy | E38: supplement | F38: 45 | G38: =F38*12 -> 540 | H38: 1 packet daily (~1 g sodium) | I38: hydration, energy, cramps | J38: partial | K38: Resting heart rate; sleep | M38: fast: acts and clears within hours | N38: 3 days on, 3 days off, for 14 days | O38: yes | P38: 0.1 | Q38: No sleep effect to expect. | R38: not tested | S38: 3 | T38: Can't measure it | U38: 3 | V38: no | X38: no dose rule | Y38: C | Z38: Useful if you sweat heavily or eat very low-carb. For a normal day, plain water does the same and the extra sodium isn't helpful. | AA38: weak | AC38: Trains over 1 h/day or keto: Tier 3 keep. Otherwise Tier 3 with 'water does this'. Goal sleep: Tier 1. | AD38: frequency | AE38: How many times in the last 30 days? | AF38: training sessions over an hour, per week | AG38: Training over an hour a day, or keto → Tier 3 keep. Otherwise Tier 3 with 'water does this'. Fires the frequency question for training, not for the product. | AH38: electrolytes | AI38: High blood pressure: a gram of sodium a day on top of diet is not trivial. | AJ38: If you're sweating hard for an hour a day, this earns its place. If you're not, water does the same job, and this is mostly salt and flavour at $45 a month. | AK38: no
A39: 38 | B39: greens-powder-ag1-etc | C39: Greens powder (AG1 etc.) | D39: buy | E39: supplement | F39: 90 | G39: =F39*12 -> 1080 | H39: 1 scoop | I39: general health, energy, gut | J39: no | M39: slow: builds up or clears over weeks | N39: no experiment | O39: no | R39: not tested | S39: 3 | T39: Can't measure it | U39: 3 | V39: no | X39: no dose rule | Y39: D | Z39: There are no independent studies of the product. It's a low-dose multivitamin plus a blend of ingredients whose amounts aren't disclosed. | AA39: weak | AC39: Tier 3 (untestable). Verdict shows annual cost prominently. | AD39: still paying | AE39: Still paying for it? | AF39: Yes · no · not sure. Prefilled from the subscriptions list where the person connected one. | AG39: still paying = yes → Tier 3 with annual cost. Overlap group 'daily multivitamin' → overlap check. | AH39: daily multivitamin | AJ39: We can't measure this one and neither has anyone else; there are no independent trials. What we can show you is that it's over a thousand dollars a year. That's the whole verdict, and the call is yours. | AK39: yes | AL39: No independent trials. Search PubMed for the brand; note funding of anything found.
